#VRML_SIM R2021a utf8
WorldInfo {
  coordinateSystem "NUE"
}
Viewpoint {
  orientation -0.9897403082638442 -0.09831326859264124 -0.1036755680786057 0.314823198154074
  position -1.1037759208156073 1.5031796041747492 4.218489383830676
  follow "rectangle arena"
}
TexturedBackground {
}
TexturedBackgroundLight {
}
RectangleArena {
  floorSize 5 5
  floorAppearance Parquetry {
    type "light strip"
  }
  wallHeight 0.3
}
WoodenBox {
  translation 0.3 0.05 0
  size 0.1 0.1 0.1
}
WoodenBox {
  translation 0.02 0.05 -0.46
  name "wooden box(1)"
  size 0.1 0.1 0.1
}
WoodenBox {
  translation -1.02 0.05 -0.46
  name "wooden box(2)"
  size 0.1 0.1 0.1
}
WoodenBox {
  translation -1.02 0.05 0.94
  name "wooden box(3)"
  size 0.1 0.1 0.1
}
WoodenBox {
  translation -0.4 0.05 0.6
  name "wooden box(4)"
  size 0.1 0.1 0.1
}
WoodenBox {
  translation -0.4 0.05 -1.25
  name "wooden box(5)"
  size 0.1 0.1 0.1
}
WoodenBox {
  translation 0.69 0.05 -1.25
  name "wooden box(6)"
  size 0.1 0.1 0.1
}
WoodenBox {
  translation 0.46 0.05 0.87
  name "wooden box(7)"
  size 0.1 0.1 0.1
}
WoodenBox {
  translation -1.54 0.05 0.31
  name "wooden box(8)"
  size 0.1 0.1 0.1
}
WoodenBox {
  translation 1.09 0.05 0.53
  name "wooden box(9)"
  size 0.1 0.1 0.1
}
WoodenBox {
  translation 2.15 0.05 -0.35
  name "wooden box(10)"
  size 0.1 0.1 0.1
}
WoodenBox {
  translation 1.99 0.05 1.23
  name "wooden box(20)"
  size 0.1 0.1 0.1
}
WoodenBox {
  translation 1.52 0.05 1.13
  name "wooden box(21)"
  size 0.1 0.1 0.1
}
WoodenBox {
  translation 0.72 0.05 -0.83
  name "wooden box(22)"
  size 0.1 0.1 0.1
}
WoodenBox {
  translation 1.74 0.05 -1.64
  name "wooden box(23)"
  size 0.1 0.1 0.1
}
WoodenBox {
  translation 1.52 0.05 -0.46
  name "wooden box(24)"
  size 0.1 0.1 0.1
}
WoodenBox {
  translation 2.39 0.05 -1.61
  name "wooden box(25)"
  size 0.1 0.1 0.1
}
WoodenBox {
  translation -0.56 0.05 -0.5
  name "wooden box(11)"
  size 0.1 0.1 0.1
}
WoodenBox {
  translation -0.82 0.05 1.89
  name "wooden box(12)"
  size 0.1 0.1 0.1
}
WoodenBox {
  translation 0.12 0.05 1.66
  name "wooden box(26)"
  size 0.1 0.1 0.1
}
WoodenBox {
  translation 0.12 0.05 2.28
  name "wooden box(27)"
  size 0.1 0.1 0.1
}
WoodenBox {
  translation -0.55 0.05 1.33
  name "wooden box(28)"
  size 0.1 0.1 0.1
}
WoodenBox {
  translation -1.48 0.05 1.36
  name "wooden box(29)"
  size 0.1 0.1 0.1
}
WoodenBox {
  translation -2.05 0.05 -1.93
  name "wooden box(13)"
  size 0.1 0.1 0.1
}
WoodenBox {
  translation -2.14 0.05 1.09
  name "wooden box(14)"
  size 0.1 0.1 0.1
}
WoodenBox {
  translation 0.22 0.05 -1.78
  name "wooden box(15)"
  size 0.1 0.1 0.1
}
WoodenBox {
  translation 0.95 0.05 1.5
  name "wooden box(16)"
  size 0.1 0.1 0.1
}
WoodenBox {
  translation -0.98 0.05 -1.38
  name "wooden box(17)"
  size 0.1 0.1 0.1
}
WoodenBox {
  translation 1.64 0.05 0.57
  name "wooden box(18)"
  size 0.1 0.1 0.1
}
WoodenBox {
  translation -1.92 0.05 -0.92
  name "wooden box(19)"
  size 0.1 0.1 0.1
}
DEF chicken Robot {
  translation -1.02471 0.07 -1.05362
  rotation 0 1 0 2.3562
  children [
    HingeJoint {
      jointParameters HingeJointParameters {
        anchor -0.071726 0 0.0642287
      }
      device [
        RotationalMotor {
          name "leg3"
        }
      ]
      endPoint Solid {
        translation -0.07172596245637175 -0.02921937482770335 0.06422869089424102
        rotation 1 0 0 0
        children [
          DEF leg Shape {
            appearance PBRAppearance {
            }
            geometry Capsule {
              height 0.04
              radius 0.02
            }
          }
        ]
        name "animalHinge"
        boundingObject USE leg
        physics DEF Physics_wh Physics {
        }
      }
    }
    HingeJoint {
      jointParameters HingeJointParameters {
        anchor -0.0705216 0 -0.0525174
      }
      device [
        RotationalMotor {
          name "leg4"
        }
      ]
      endPoint Solid {
        translation -0.07052159839181898 -0.03127634768018899 -0.0525174301346117
        rotation -0.0017681284167292944 -0.799324101915746 -0.6008975402000645 0.0033614498136678044
        children [
          USE leg
        ]
        name "animalHinge1"
        boundingObject USE leg
        physics DEF Physics_wh Physics {
        }
      }
    }
    HingeJoint {
      jointParameters HingeJointParameters {
        anchor 0.0694427 0 0.0633882
      }
      device [
        RotationalMotor {
          name "leg1"
        }
      ]
      endPoint Solid {
        translation 0.0694427439142312 -0.029239266431092245 0.06338818551357624
        rotation -0.0007300225117002297 -0.9962523175163163 -0.08649154242179594 0.004789506714649732
        children [
          USE leg
        ]
        name "animalHinge(2)"
        boundingObject USE leg
        physics DEF Physics_wh Physics {
        }
      }
    }
    HingeJoint {
      jointParameters HingeJointParameters {
        anchor 0.0705551 0 -0.0516104
      }
      device [
        RotationalMotor {
          name "leg2"
        }
      ]
      endPoint Solid {
        translation 0.07055508848613092 -0.033114116965949125 -0.05161039057340424
        rotation -0.00016116905963040924 -0.9977504345617875 -0.06703763388051748 0.002606059777910019
        children [
          USE leg
        ]
        name "animalHinge(3)"
        boundingObject USE leg
        physics DEF Physics_wh Physics {
        }
      }
    }
    DistanceSensor {
      translation -0.0514405 0 0.0966085
      rotation 0 -1 0 2.785395307179586
      children [
        DEF sensor Shape {
          appearance PBRAppearance {
            baseColor 0 0 1
          }
          geometry Box {
            size 0.01 0.01 0.01
          }
        }
      ]
      name "ds_right(1)"
      boundingObject USE sensor
      physics Physics {
      }
    }
    DistanceSensor {
      translation 0.0523081 0 0.100369
      rotation 0 -1 0 0.364016
      children [
        DEF sensor Shape {
          appearance PBRAppearance {
            baseColor 0 0 1
          }
          geometry Box {
            size 0.01 0.01 0.01
          }
        }
      ]
      name "ds_left(1)"
      boundingObject USE sensor
      physics Physics {
      }
    }
    DistanceSensor {
      translation 0.02 0 0.1
      rotation 0 -1 0 0.738201
      children [
        DEF sensor Shape {
          appearance PBRAppearance {
            baseColor 0 0 1
          }
          geometry Box {
            size 0.01 0.01 0.01
          }
        }
      ]
      name "ds_left"
      boundingObject USE sensor
      physics Physics {
      }
    }
    DistanceSensor {
      translation -0.02 0 0.1
      rotation 0 1 0 -2.261795307179586
      children [
        DEF sensor Shape {
          appearance PBRAppearance {
            baseColor 0 0 1
          }
          geometry Box {
            size 0.01 0.01 0.01
          }
        }
      ]
      name "ds_right"
      boundingObject USE sensor
      physics Physics {
      }
    }
    Camera {
      translation -2.6536e-07 0 0.1
      rotation 0 1 0 3.14159
      children [
        Shape {
          appearance PBRAppearance {
            baseColor 1 0 1
          }
          geometry Box {
            size 0.01 0.01 0.01
          }
        }
      ]
      recognitionColors [
        1 1 0
      ]
      fieldOfView 1
      width 1080
      height 720
      recognition Recognition {
      }
    }
    DEF Body Shape {
      appearance PBRAppearance {
      }
      geometry Box {
        size 0.1 0.05 0.2
      }
    }
  ]
  name "robot(1)"
  boundingObject DEF Body Shape {
    appearance PBRAppearance {
    }
    geometry Box {
      size 0.1 0.05 0.2
    }
  }
  physics DEF Physics_wh Physics {
  }
  controller "Chicken_Controller"
  supervisor TRUE
}
DEF chicken1 Robot {
  translation -1.32771 0.07 -0.211166
  rotation 0 1 0 -2.356185307179586
  children [
    HingeJoint {
      jointParameters HingeJointParameters {
        anchor -0.071726 0 0.0642287
      }
      device [
        RotationalMotor {
          name "leg3"
        }
      ]
      endPoint Solid {
        translation -0.07172596245637175 -0.02921937482770335 0.06422869089424102
        rotation 1 0 0 0
        children [
          DEF leg Shape {
            appearance PBRAppearance {
            }
            geometry Capsule {
              height 0.04
              radius 0.02
            }
          }
        ]
        name "animalHinge"
        boundingObject USE leg
        physics DEF Physics_wh Physics {
        }
      }
    }
    HingeJoint {
      jointParameters HingeJointParameters {
        anchor -0.0705216 0 -0.0525174
      }
      device [
        RotationalMotor {
          name "leg4"
        }
      ]
      endPoint Solid {
        translation -0.07052159839181898 -0.03127634768018899 -0.0525174301346117
        rotation -0.0017681284167292944 -0.799324101915746 -0.6008975402000645 0.0033614498136678044
        children [
          USE leg
        ]
        name "animalHinge1"
        boundingObject USE leg
        physics DEF Physics_wh Physics {
        }
      }
    }
    HingeJoint {
      jointParameters HingeJointParameters {
        anchor 0.0694427 0 0.0633882
      }
      device [
        RotationalMotor {
          name "leg1"
        }
      ]
      endPoint Solid {
        translation 0.0694427439142312 -0.029239266431092245 0.06338818551357624
        rotation -0.0007300225117002297 -0.9962523175163163 -0.08649154242179594 0.004789506714649732
        children [
          USE leg
        ]
        name "animalHinge(2)"
        boundingObject USE leg
        physics DEF Physics_wh Physics {
        }
      }
    }
    HingeJoint {
      jointParameters HingeJointParameters {
        anchor 0.0705551 0 -0.0516104
      }
      device [
        RotationalMotor {
          name "leg2"
        }
      ]
      endPoint Solid {
        translation 0.07055508848613092 -0.033114116965949125 -0.05161039057340424
        rotation -0.00016116905963040924 -0.9977504345617875 -0.06703763388051748 0.002606059777910019
        children [
          USE leg
        ]
        name "animalHinge(3)"
        boundingObject USE leg
        physics DEF Physics_wh Physics {
        }
      }
    }
    DistanceSensor {
      translation -0.0514405 0 0.0966085
      rotation 0 -1 0 2.785395307179586
      children [
        DEF sensor Shape {
          appearance PBRAppearance {
            baseColor 0 0 1
          }
          geometry Box {
            size 0.01 0.01 0.01
          }
        }
      ]
      name "ds_right(1)"
      boundingObject USE sensor
      physics Physics {
      }
    }
    DistanceSensor {
      translation 0.0523081 0 0.100369
      rotation 0 -1 0 0.364016
      children [
        DEF sensor Shape {
          appearance PBRAppearance {
            baseColor 0 0 1
          }
          geometry Box {
            size 0.01 0.01 0.01
          }
        }
      ]
      name "ds_left(1)"
      boundingObject USE sensor
      physics Physics {
      }
    }
    DistanceSensor {
      translation 0.02 0 0.1
      rotation 0 -1 0 0.738201
      children [
        DEF sensor Shape {
          appearance PBRAppearance {
            baseColor 0 0 1
          }
          geometry Box {
            size 0.01 0.01 0.01
          }
        }
      ]
      name "ds_left"
      boundingObject USE sensor
      physics Physics {
      }
    }
    DistanceSensor {
      translation -0.02 0 0.1
      rotation 0 1 0 -2.261795307179586
      children [
        DEF sensor Shape {
          appearance PBRAppearance {
            baseColor 0 0 1
          }
          geometry Box {
            size 0.01 0.01 0.01
          }
        }
      ]
      name "ds_right"
      boundingObject USE sensor
      physics Physics {
      }
    }
    Camera {
      translation -2.6536e-07 0 0.1
      rotation 0 1 0 3.14159
      children [
        Shape {
          appearance PBRAppearance {
            baseColor 1 0 1
          }
          geometry Box {
            size 0.01 0.01 0.01
          }
        }
      ]
      recognitionColors [
        1 1 0
      ]
      fieldOfView 1
      width 1080
      height 720
      recognition Recognition {
      }
    }
    DEF Body Shape {
      appearance PBRAppearance {
      }
      geometry Box {
        size 0.1 0.05 0.2
      }
    }
  ]
  name "robot(2)"
  boundingObject DEF Body Shape {
    appearance PBRAppearance {
    }
    geometry Box {
      size 0.1 0.05 0.2
    }
  }
  physics DEF Physics_wh Physics {
  }
  controller "Chicken_Controller1"
  supervisor TRUE
}
DEF chicken2 Robot {
  translation -0.161277 0.07 -1.43599
  rotation 0 -1 0 -0.7854053071795866
  children [
    HingeJoint {
      jointParameters HingeJointParameters {
        anchor -0.071726 0 0.0642287
      }
      device [
        RotationalMotor {
          name "leg3"
        }
      ]
      endPoint Solid {
        translation -0.07172596245637175 -0.02921937482770335 0.06422869089424102
        rotation 1 0 0 0
        children [
          DEF leg Shape {
            appearance PBRAppearance {
            }
            geometry Capsule {
              height 0.04
              radius 0.02
            }
          }
        ]
        name "animalHinge"
        boundingObject USE leg
        physics DEF Physics_wh Physics {
        }
      }
    }
    HingeJoint {
      jointParameters HingeJointParameters {
        anchor -0.0705216 0 -0.0525174
      }
      device [
        RotationalMotor {
          name "leg4"
        }
      ]
      endPoint Solid {
        translation -0.07052159839181898 -0.03127634768018899 -0.0525174301346117
        rotation -0.0017681284167292944 -0.799324101915746 -0.6008975402000645 0.0033614498136678044
        children [
          USE leg
        ]
        name "animalHinge1"
        boundingObject USE leg
        physics DEF Physics_wh Physics {
        }
      }
    }
    HingeJoint {
      jointParameters HingeJointParameters {
        anchor 0.0694427 0 0.0633882
      }
      device [
        RotationalMotor {
          name "leg1"
        }
      ]
      endPoint Solid {
        translation 0.0694427439142312 -0.029239266431092245 0.06338818551357624
        rotation -0.0007300225117002297 -0.9962523175163163 -0.08649154242179594 0.004789506714649732
        children [
          USE leg
        ]
        name "animalHinge(2)"
        boundingObject USE leg
        physics DEF Physics_wh Physics {
        }
      }
    }
    HingeJoint {
      jointParameters HingeJointParameters {
        anchor 0.0705551 0 -0.0516104
      }
      device [
        RotationalMotor {
          name "leg2"
        }
      ]
      endPoint Solid {
        translation 0.07055508848613092 -0.033114116965949125 -0.05161039057340424
        rotation -0.00016116905963040924 -0.9977504345617875 -0.06703763388051748 0.002606059777910019
        children [
          USE leg
        ]
        name "animalHinge(3)"
        boundingObject USE leg
        physics DEF Physics_wh Physics {
        }
      }
    }
    DistanceSensor {
      translation -0.0514405 0 0.0966085
      rotation 0 -1 0 2.785395307179586
      children [
        DEF sensor Shape {
          appearance PBRAppearance {
            baseColor 0 0 1
          }
          geometry Box {
            size 0.01 0.01 0.01
          }
        }
      ]
      name "ds_right(1)"
      boundingObject USE sensor
      physics Physics {
      }
    }
    DistanceSensor {
      translation 0.0523081 0 0.100369
      rotation 0 -1 0 0.364016
      children [
        DEF sensor Shape {
          appearance PBRAppearance {
            baseColor 0 0 1
          }
          geometry Box {
            size 0.01 0.01 0.01
          }
        }
      ]
      name "ds_left(1)"
      boundingObject USE sensor
      physics Physics {
      }
    }
    DistanceSensor {
      translation 0.02 0 0.1
      rotation 0 -1 0 0.738201
      children [
        DEF sensor Shape {
          appearance PBRAppearance {
            baseColor 0 0 1
          }
          geometry Box {
            size 0.01 0.01 0.01
          }
        }
      ]
      name "ds_left"
      boundingObject USE sensor
      physics Physics {
      }
    }
    DistanceSensor {
      translation -0.02 0 0.1
      rotation 0 1 0 -2.261795307179586
      children [
        DEF sensor Shape {
          appearance PBRAppearance {
            baseColor 0 0 1
          }
          geometry Box {
            size 0.01 0.01 0.01
          }
        }
      ]
      name "ds_right"
      boundingObject USE sensor
      physics Physics {
      }
    }
    Camera {
      translation -2.6536e-07 0 0.1
      rotation 0 1 0 3.14159
      children [
        Shape {
          appearance PBRAppearance {
            baseColor 1 0 1
          }
          geometry Box {
            size 0.01 0.01 0.01
          }
        }
      ]
      recognitionColors [
        1 1 0
      ]
      fieldOfView 1
      width 1080
      height 720
      recognition Recognition {
      }
    }
    DEF Body Shape {
      appearance PBRAppearance {
      }
      geometry Box {
        size 0.1 0.05 0.2
      }
    }
  ]
  name "robot(3)"
  boundingObject DEF Body Shape {
    appearance PBRAppearance {
    }
    geometry Box {
      size 0.1 0.05 0.2
    }
  }
  physics DEF Physics_wh Physics {
  }
  controller "Chicken_Controller2"
  supervisor TRUE
}
DEF chicken3 Robot {
  translation -0.235804 0.07 0.385814
  rotation 0 -1 0 -0.5236053071795865
  children [
    HingeJoint {
      jointParameters HingeJointParameters {
        anchor -0.071726 0 0.0642287
      }
      device [
        RotationalMotor {
          name "leg3"
        }
      ]
      endPoint Solid {
        translation -0.07172596245637175 -0.02921937482770335 0.06422869089424102
        rotation 1 0 0 0
        children [
          DEF leg Shape {
            appearance PBRAppearance {
            }
            geometry Capsule {
              height 0.04
              radius 0.02
            }
          }
        ]
        name "animalHinge"
        boundingObject USE leg
        physics DEF Physics_wh Physics {
        }
      }
    }
    HingeJoint {
      jointParameters HingeJointParameters {
        anchor -0.0705216 0 -0.0525174
      }
      device [
        RotationalMotor {
          name "leg4"
        }
      ]
      endPoint Solid {
        translation -0.07052159839181898 -0.03127634768018899 -0.0525174301346117
        rotation -0.0017681284167292944 -0.799324101915746 -0.6008975402000645 0.0033614498136678044
        children [
          USE leg
        ]
        name "animalHinge1"
        boundingObject USE leg
        physics DEF Physics_wh Physics {
        }
      }
    }
    HingeJoint {
      jointParameters HingeJointParameters {
        anchor 0.0694427 0 0.0633882
      }
      device [
        RotationalMotor {
          name "leg1"
        }
      ]
      endPoint Solid {
        translation 0.0694427439142312 -0.029239266431092245 0.06338818551357624
        rotation -0.0007300225117002297 -0.9962523175163163 -0.08649154242179594 0.004789506714649732
        children [
          USE leg
        ]
        name "animalHinge(2)"
        boundingObject USE leg
        physics DEF Physics_wh Physics {
        }
      }
    }
    HingeJoint {
      jointParameters HingeJointParameters {
        anchor 0.0705551 0 -0.0516104
      }
      device [
        RotationalMotor {
          name "leg2"
        }
      ]
      endPoint Solid {
        translation 0.07055508848613092 -0.033114116965949125 -0.05161039057340424
        rotation -0.00016116905963040924 -0.9977504345617875 -0.06703763388051748 0.002606059777910019
        children [
          USE leg
        ]
        name "animalHinge(3)"
        boundingObject USE leg
        physics DEF Physics_wh Physics {
        }
      }
    }
    DistanceSensor {
      translation -0.0514405 0 0.0966085
      rotation 0 -1 0 2.785395307179586
      children [
        DEF sensor Shape {
          appearance PBRAppearance {
            baseColor 0 0 1
          }
          geometry Box {
            size 0.01 0.01 0.01
          }
        }
      ]
      name "ds_right(1)"
      boundingObject USE sensor
      physics Physics {
      }
    }
    DistanceSensor {
      translation 0.0523081 0 0.100369
      rotation 0 -1 0 0.364016
      children [
        DEF sensor Shape {
          appearance PBRAppearance {
            baseColor 0 0 1
          }
          geometry Box {
            size 0.01 0.01 0.01
          }
        }
      ]
      name "ds_left(1)"
      boundingObject USE sensor
      physics Physics {
      }
    }
    DistanceSensor {
      translation 0.02 0 0.1
      rotation 0 -1 0 0.738201
      children [
        DEF sensor Shape {
          appearance PBRAppearance {
            baseColor 0 0 1
          }
          geometry Box {
            size 0.01 0.01 0.01
          }
        }
      ]
      name "ds_left"
      boundingObject USE sensor
      physics Physics {
      }
    }
    DistanceSensor {
      translation -0.02 0 0.1
      rotation 0 1 0 -2.261795307179586
      children [
        DEF sensor Shape {
          appearance PBRAppearance {
            baseColor 0 0 1
          }
          geometry Box {
            size 0.01 0.01 0.01
          }
        }
      ]
      name "ds_right"
      boundingObject USE sensor
      physics Physics {
      }
    }
    Camera {
      translation -2.6536e-07 0 0.1
      rotation 0 1 0 3.14159
      children [
        Shape {
          appearance PBRAppearance {
            baseColor 1 0 1
          }
          geometry Box {
            size 0.01 0.01 0.01
          }
        }
      ]
      recognitionColors [
        1 1 0
      ]
      fieldOfView 1
      width 1080
      height 720
      recognition Recognition {
      }
    }
    DEF Body Shape {
      appearance PBRAppearance {
      }
      geometry Box {
        size 0.1 0.05 0.2
      }
    }
  ]
  name "robot(4)"
  boundingObject DEF Body Shape {
    appearance PBRAppearance {
    }
    geometry Box {
      size 0.1 0.05 0.2
    }
  }
  physics DEF Physics_wh Physics {
  }
  controller "Chicken_Controller3"
  supervisor TRUE
}
DEF chicken4 Robot {
  translation -1.25299 0.07 1.60295
  rotation 0 1 0 -3.1415853071795863
  children [
    HingeJoint {
      jointParameters HingeJointParameters {
        anchor -0.071726 0 0.0642287
      }
      device [
        RotationalMotor {
          name "leg3"
        }
      ]
      endPoint Solid {
        translation -0.07172596245637175 -0.02921937482770335 0.06422869089424102
        rotation 1 0 0 0
        children [
          DEF leg Shape {
            appearance PBRAppearance {
            }
            geometry Capsule {
              height 0.04
              radius 0.02
            }
          }
        ]
        name "animalHinge"
        boundingObject USE leg
        physics DEF Physics_wh Physics {
        }
      }
    }
    HingeJoint {
      jointParameters HingeJointParameters {
        anchor -0.0705216 0 -0.0525174
      }
      device [
        RotationalMotor {
          name "leg4"
        }
      ]
      endPoint Solid {
        translation -0.07052159839181898 -0.03127634768018899 -0.0525174301346117
        rotation -0.0017681284167292944 -0.799324101915746 -0.6008975402000645 0.0033614498136678044
        children [
          USE leg
        ]
        name "animalHinge1"
        boundingObject USE leg
        physics DEF Physics_wh Physics {
        }
      }
    }
    HingeJoint {
      jointParameters HingeJointParameters {
        anchor 0.0694427 0 0.0633882
      }
      device [
        RotationalMotor {
          name "leg1"
        }
      ]
      endPoint Solid {
        translation 0.0694427439142312 -0.029239266431092245 0.06338818551357624
        rotation -0.0007300225117002297 -0.9962523175163163 -0.08649154242179594 0.004789506714649732
        children [
          USE leg
        ]
        name "animalHinge(2)"
        boundingObject USE leg
        physics DEF Physics_wh Physics {
        }
      }
    }
    HingeJoint {
      jointParameters HingeJointParameters {
        anchor 0.0705551 0 -0.0516104
      }
      device [
        RotationalMotor {
          name "leg2"
        }
      ]
      endPoint Solid {
        translation 0.07055508848613092 -0.033114116965949125 -0.05161039057340424
        rotation -0.00016116905963040924 -0.9977504345617875 -0.06703763388051748 0.002606059777910019
        children [
          USE leg
        ]
        name "animalHinge(3)"
        boundingObject USE leg
        physics DEF Physics_wh Physics {
        }
      }
    }
    DistanceSensor {
      translation -0.0514405 0 0.0966085
      rotation 0 -1 0 2.785395307179586
      children [
        DEF sensor Shape {
          appearance PBRAppearance {
            baseColor 0 0 1
          }
          geometry Box {
            size 0.01 0.01 0.01
          }
        }
      ]
      name "ds_right(1)"
      boundingObject USE sensor
      physics Physics {
      }
    }
    DistanceSensor {
      translation 0.0523081 0 0.100369
      rotation 0 -1 0 0.364016
      children [
        DEF sensor Shape {
          appearance PBRAppearance {
            baseColor 0 0 1
          }
          geometry Box {
            size 0.01 0.01 0.01
          }
        }
      ]
      name "ds_left(1)"
      boundingObject USE sensor
      physics Physics {
      }
    }
    DistanceSensor {
      translation 0.02 0 0.1
      rotation 0 -1 0 0.738201
      children [
        DEF sensor Shape {
          appearance PBRAppearance {
            baseColor 0 0 1
          }
          geometry Box {
            size 0.01 0.01 0.01
          }
        }
      ]
      name "ds_left"
      boundingObject USE sensor
      physics Physics {
      }
    }
    DistanceSensor {
      translation -0.02 0 0.1
      rotation 0 1 0 -2.261795307179586
      children [
        DEF sensor Shape {
          appearance PBRAppearance {
            baseColor 0 0 1
          }
          geometry Box {
            size 0.01 0.01 0.01
          }
        }
      ]
      name "ds_right"
      boundingObject USE sensor
      physics Physics {
      }
    }
    Camera {
      translation -2.6536e-07 0 0.1
      rotation 0 1 0 3.14159
      children [
        Shape {
          appearance PBRAppearance {
            baseColor 1 0 1
          }
          geometry Box {
            size 0.01 0.01 0.01
          }
        }
      ]
      recognitionColors [
        1 1 0
      ]
      fieldOfView 1
      width 1080
      height 720
      recognition Recognition {
      }
    }
    DEF Body Shape {
      appearance PBRAppearance {
      }
      geometry Box {
        size 0.1 0.05 0.2
      }
    }
  ]
  name "robot(5)"
  boundingObject DEF Body Shape {
    appearance PBRAppearance {
    }
    geometry Box {
      size 0.1 0.05 0.2
    }
  }
  physics DEF Physics_wh Physics {
  }
  controller "Chicken_Controller4"
  supervisor TRUE
}
DEF chicken5 Robot {
  translation 1.82946 0.07 0.260547
  rotation 0 1 0 2.0944
  children [
    HingeJoint {
      jointParameters HingeJointParameters {
        anchor -0.071726 0 0.0642287
      }
      device [
        RotationalMotor {
          name "leg3"
        }
      ]
      endPoint Solid {
        translation -0.07172596245637175 -0.02921937482770335 0.06422869089424102
        rotation 1 0 0 0
        children [
          DEF leg Shape {
            appearance PBRAppearance {
            }
            geometry Capsule {
              height 0.04
              radius 0.02
            }
          }
        ]
        name "animalHinge"
        boundingObject USE leg
        physics DEF Physics_wh Physics {
        }
      }
    }
    HingeJoint {
      jointParameters HingeJointParameters {
        anchor -0.0705216 0 -0.0525174
      }
      device [
        RotationalMotor {
          name "leg4"
        }
      ]
      endPoint Solid {
        translation -0.07052159839181898 -0.03127634768018899 -0.0525174301346117
        rotation -0.0017681284167292944 -0.799324101915746 -0.6008975402000645 0.0033614498136678044
        children [
          USE leg
        ]
        name "animalHinge1"
        boundingObject USE leg
        physics DEF Physics_wh Physics {
        }
      }
    }
    HingeJoint {
      jointParameters HingeJointParameters {
        anchor 0.0694427 0 0.0633882
      }
      device [
        RotationalMotor {
          name "leg1"
        }
      ]
      endPoint Solid {
        translation 0.0694427439142312 -0.029239266431092245 0.06338818551357624
        rotation -0.0007300225117002297 -0.9962523175163163 -0.08649154242179594 0.004789506714649732
        children [
          USE leg
        ]
        name "animalHinge(2)"
        boundingObject USE leg
        physics DEF Physics_wh Physics {
        }
      }
    }
    HingeJoint {
      jointParameters HingeJointParameters {
        anchor 0.0705551 0 -0.0516104
      }
      device [
        RotationalMotor {
          name "leg2"
        }
      ]
      endPoint Solid {
        translation 0.07055508848613092 -0.033114116965949125 -0.05161039057340424
        rotation -0.00016116905963040924 -0.9977504345617875 -0.06703763388051748 0.002606059777910019
        children [
          USE leg
        ]
        name "animalHinge(3)"
        boundingObject USE leg
        physics DEF Physics_wh Physics {
        }
      }
    }
    DistanceSensor {
      translation -0.0514405 0 0.0966085
      rotation 0 -1 0 2.785395307179586
      children [
        DEF sensor Shape {
          appearance PBRAppearance {
            baseColor 0 0 1
          }
          geometry Box {
            size 0.01 0.01 0.01
          }
        }
      ]
      name "ds_right(1)"
      boundingObject USE sensor
      physics Physics {
      }
    }
    DistanceSensor {
      translation 0.0523081 0 0.100369
      rotation 0 -1 0 0.364016
      children [
        DEF sensor Shape {
          appearance PBRAppearance {
            baseColor 0 0 1
          }
          geometry Box {
            size 0.01 0.01 0.01
          }
        }
      ]
      name "ds_left(1)"
      boundingObject USE sensor
      physics Physics {
      }
    }
    DistanceSensor {
      translation 0.02 0 0.1
      rotation 0 -1 0 0.738201
      children [
        DEF sensor Shape {
          appearance PBRAppearance {
            baseColor 0 0 1
          }
          geometry Box {
            size 0.01 0.01 0.01
          }
        }
      ]
      name "ds_left"
      boundingObject USE sensor
      physics Physics {
      }
    }
    DistanceSensor {
      translation -0.02 0 0.1
      rotation 0 1 0 -2.261795307179586
      children [
        DEF sensor Shape {
          appearance PBRAppearance {
            baseColor 0 0 1
          }
          geometry Box {
            size 0.01 0.01 0.01
          }
        }
      ]
      name "ds_right"
      boundingObject USE sensor
      physics Physics {
      }
    }
    Camera {
      translation -2.6536e-07 0 0.1
      rotation 0 1 0 3.14159
      children [
        Shape {
          appearance PBRAppearance {
            baseColor 1 0 1
          }
          geometry Box {
            size 0.01 0.01 0.01
          }
        }
      ]
      recognitionColors [
        1 1 0
      ]
      fieldOfView 1
      width 1080
      height 720
      recognition Recognition {
      }
    }
    DEF Body Shape {
      appearance PBRAppearance {
      }
      geometry Box {
        size 0.1 0.05 0.2
      }
    }
  ]
  name "robot(6)"
  boundingObject DEF Body Shape {
    appearance PBRAppearance {
    }
    geometry Box {
      size 0.1 0.05 0.2
    }
  }
  physics DEF Physics_wh Physics {
  }
  controller "Chicken_Controller5"
  supervisor TRUE
}
DEF chicken6 Robot {
  translation -1.97478 0.07 1.14525
  rotation 0 1 0 2.8798
  children [
    HingeJoint {
      jointParameters HingeJointParameters {
        anchor -0.071726 0 0.0642287
      }
      device [
        RotationalMotor {
          name "leg3"
        }
      ]
      endPoint Solid {
        translation -0.07172596245637175 -0.02921937482770334 0.06422869089424102
        rotation 1 0 0 0
        children [
          DEF leg Shape {
            appearance PBRAppearance {
            }
            geometry Capsule {
              height 0.04
              radius 0.02
            }
          }
        ]
        name "animalHinge"
        boundingObject USE leg
        physics DEF Physics_wh Physics {
        }
      }
    }
    HingeJoint {
      jointParameters HingeJointParameters {
        anchor -0.0705216 0 -0.0525174
      }
      device [
        RotationalMotor {
          name "leg4"
        }
      ]
      endPoint Solid {
        translation -0.07052159839181898 -0.03127634768018897 -0.0525174301346117
        rotation -0.0017681284170809658 -0.7993241019157451 -0.6008975402000645 0.003361449813271467
        children [
          USE leg
        ]
        name "animalHinge1"
        boundingObject USE leg
        physics DEF Physics_wh Physics {
        }
      }
    }
    HingeJoint {
      jointParameters HingeJointParameters {
        anchor 0.0694427 0 0.0633882
      }
      device [
        RotationalMotor {
          name "leg1"
        }
      ]
      endPoint Solid {
        translation 0.0694427439142312 -0.02923926643109227 0.06338818551357624
        rotation -0.000730022511644634 -0.9962523175163163 -0.086491542421796 0.004789506714371569
        children [
          USE leg
        ]
        name "animalHinge(2)"
        boundingObject USE leg
        physics DEF Physics_wh Physics {
        }
      }
    }
    HingeJoint {
      jointParameters HingeJointParameters {
        anchor 0.0705551 0 -0.0516104
      }
      device [
        RotationalMotor {
          name "leg2"
        }
      ]
      endPoint Solid {
        translation 0.07055508848613092 -0.03311411696594912 -0.05161039057340424
        rotation -0.00016116905940470445 -0.9977504345617876 -0.06703763388051738 0.002606059777910019
        children [
          USE leg
        ]
        name "animalHinge(3)"
        boundingObject USE leg
        physics DEF Physics_wh Physics {
        }
      }
    }
    DistanceSensor {
      translation -0.0514405 0 0.0966085
      rotation 0 -1 0 2.785395307179586
      children [
        DEF sensor Shape {
          appearance PBRAppearance {
            baseColor 0 0 1
          }
          geometry Box {
            size 0.01 0.01 0.01
          }
        }
      ]
      name "ds_right(1)"
      boundingObject USE sensor
      physics Physics {
      }
    }
    DistanceSensor {
      translation 0.0523081 0 0.100369
      rotation 0 -1 0 0.364016
      children [
        DEF sensor Shape {
          appearance PBRAppearance {
            baseColor 0 0 1
          }
          geometry Box {
            size 0.01 0.01 0.01
          }
        }
      ]
      name "ds_left(1)"
      boundingObject USE sensor
      physics Physics {
      }
    }
    DistanceSensor {
      translation 0.02 0 0.1
      rotation 0 -1 0 0.738201
      children [
        DEF sensor Shape {
          appearance PBRAppearance {
            baseColor 0 0 1
          }
          geometry Box {
            size 0.01 0.01 0.01
          }
        }
      ]
      name "ds_left"
      boundingObject USE sensor
      physics Physics {
      }
    }
    DistanceSensor {
      translation -0.02 0 0.1
      rotation 0 1 0 -2.261795307179586
      children [
        DEF sensor Shape {
          appearance PBRAppearance {
            baseColor 0 0 1
          }
          geometry Box {
            size 0.01 0.01 0.01
          }
        }
      ]
      name "ds_right"
      boundingObject USE sensor
      physics Physics {
      }
    }
    Camera {
      translation -2.6536e-07 0 0.1
      rotation 0 1 0 3.14159
      children [
        Shape {
          appearance PBRAppearance {
            baseColor 1 0 1
          }
          geometry Box {
            size 0.01 0.01 0.01
          }
        }
      ]
      fieldOfView 1
      width 1080
      height 720
      recognition Recognition {
      }
    }
    DEF Body Shape {
      appearance PBRAppearance {
      }
      geometry Box {
        size 0.1 0.05 0.2
      }
    }
  ]
  name "robot(7)"
  boundingObject DEF Body Shape {
    appearance PBRAppearance {
    }
    geometry Box {
      size 0.1 0.05 0.2
    }
  }
  physics DEF Physics_wh Physics {
  }
  recognitionColors [
    0 0 0
  ]
  controller "Chicken_Controller6"
  supervisor TRUE
}
DEF chicken7 Robot {
  translation 1.76921 0.07 -0.819307
  rotation 0 1 0 -2.0943853071795866
  children [
    HingeJoint {
      jointParameters HingeJointParameters {
        anchor -0.071726 0 0.0642287
      }
      device [
        RotationalMotor {
          name "leg3"
        }
      ]
      endPoint Solid {
        translation -0.07172596245637175 -0.02921937482770335 0.06422869089424102
        rotation 1 0 0 0
        children [
          DEF leg Shape {
            appearance PBRAppearance {
            }
            geometry Capsule {
              height 0.04
              radius 0.02
            }
          }
        ]
        name "animalHinge"
        boundingObject USE leg
        physics DEF Physics_wh Physics {
        }
      }
    }
    HingeJoint {
      jointParameters HingeJointParameters {
        anchor -0.0705216 0 -0.0525174
      }
      device [
        RotationalMotor {
          name "leg4"
        }
      ]
      endPoint Solid {
        translation -0.07052159839181898 -0.03127634768018899 -0.0525174301346117
        rotation -0.0017681284167292944 -0.799324101915746 -0.6008975402000645 0.0033614498136678044
        children [
          USE leg
        ]
        name "animalHinge1"
        boundingObject USE leg
        physics DEF Physics_wh Physics {
        }
      }
    }
    HingeJoint {
      jointParameters HingeJointParameters {
        anchor 0.0694427 0 0.0633882
      }
      device [
        RotationalMotor {
          name "leg1"
        }
      ]
      endPoint Solid {
        translation 0.0694427439142312 -0.029239266431092245 0.06338818551357624
        rotation -0.0007300225117002297 -0.9962523175163163 -0.08649154242179594 0.004789506714649732
        children [
          USE leg
        ]
        name "animalHinge(2)"
        boundingObject USE leg
        physics DEF Physics_wh Physics {
        }
      }
    }
    HingeJoint {
      jointParameters HingeJointParameters {
        anchor 0.0705551 0 -0.0516104
      }
      device [
        RotationalMotor {
          name "leg2"
        }
      ]
      endPoint Solid {
        translation 0.07055508848613092 -0.033114116965949125 -0.05161039057340424
        rotation -0.00016116905963040924 -0.9977504345617875 -0.06703763388051748 0.002606059777910019
        children [
          USE leg
        ]
        name "animalHinge(3)"
        boundingObject USE leg
        physics DEF Physics_wh Physics {
        }
      }
    }
    DistanceSensor {
      translation -0.0514405 0 0.0966085
      rotation 0 -1 0 2.785395307179586
      children [
        DEF sensor Shape {
          appearance PBRAppearance {
            baseColor 0 0 1
          }
          geometry Box {
            size 0.01 0.01 0.01
          }
        }
      ]
      name "ds_right(1)"
      boundingObject USE sensor
      physics Physics {
      }
    }
    DistanceSensor {
      translation 0.0523081 0 0.100369
      rotation 0 -1 0 0.364016
      children [
        DEF sensor Shape {
          appearance PBRAppearance {
            baseColor 0 0 1
          }
          geometry Box {
            size 0.01 0.01 0.01
          }
        }
      ]
      name "ds_left(1)"
      boundingObject USE sensor
      physics Physics {
      }
    }
    DistanceSensor {
      translation 0.02 0 0.1
      rotation 0 -1 0 0.738201
      children [
        DEF sensor Shape {
          appearance PBRAppearance {
            baseColor 0 0 1
          }
          geometry Box {
            size 0.01 0.01 0.01
          }
        }
      ]
      name "ds_left"
      boundingObject USE sensor
      physics Physics {
      }
    }
    DistanceSensor {
      translation -0.02 0 0.1
      rotation 0 1 0 -2.261795307179586
      children [
        DEF sensor Shape {
          appearance PBRAppearance {
            baseColor 0 0 1
          }
          geometry Box {
            size 0.01 0.01 0.01
          }
        }
      ]
      name "ds_right"
      boundingObject USE sensor
      physics Physics {
      }
    }
    Camera {
      translation -2.6536e-07 0 0.1
      rotation 0 1 0 3.14159
      children [
        Shape {
          appearance PBRAppearance {
            baseColor 1 0 1
          }
          geometry Box {
            size 0.01 0.01 0.01
          }
        }
      ]
      recognitionColors [
        1 1 0
      ]
      fieldOfView 1
      width 1080
      height 720
      recognition Recognition {
      }
    }
    DEF Body Shape {
      appearance PBRAppearance {
      }
      geometry Box {
        size 0.1 0.05 0.2
      }
    }
  ]
  name "robot(8)"
  boundingObject DEF Body Shape {
    appearance PBRAppearance {
    }
    geometry Box {
      size 0.1 0.05 0.2
    }
  }
  physics DEF Physics_wh Physics {
  }
  controller "Chicken_Controller7"
  supervisor TRUE
}
DEF grain Solid {
  translation 0 0.03 0
  children [
    Shape {
      appearance PBRAppearance {
      }
      geometry Box {
        size 0.3 0.06 0.2
      }
    }
  ]
  recognitionColors [
    1 1 0
  ]
}
DEF grain1 Solid {
  translation -1.22 0.04 1.17
  children [
    Shape {
      appearance PBRAppearance {
      }
      geometry Box {
        size 0.3 0.08 0.2
      }
    }
  ]
  name "solid(1)"
  recognitionColors [
    1 1 0
  ]
}
DEF grain2 Solid {
  translation -1.98 0.05 0
  children [
    Shape {
      appearance PBRAppearance {
      }
      geometry Box {
        size 0.3 0.1 0.2
      }
    }
  ]
  name "solid(2)"
  recognitionColors [
    1 1 0
  ]
}
DEF grain3 Solid {
  translation 1.17 0.03 -1.4
  children [
    Shape {
      appearance PBRAppearance {
      }
      geometry Box {
        size 0.3 0.07 0.2
      }
    }
  ]
  name "solid(3)"
  recognitionColors [
    1 1 0
  ]
}
